<robot name = "robot">
    <link name="Link0">
        <inertial>
            <origin xyz="0 0 0" rpy="0 0 0"/>
            <mass value="1" />
            <inertia ixx="100" ixy="0" ixz="0" iyy="100" iyz="0" izz="100" />
        </inertial>
        <visual>
            <origin xyz="0 0 0" rpy="0 0 0"/>
            <geometry>
                <box size="0.5772687024499288 0.8447693069846848 0.7951935655656966" />
            </geometry>
            <material name="Blue">
                <color rgba="0 0 1.0 1.0"/>
            </material>
        </visual>
        <collision>
            <origin xyz="0 0 0" rpy="0 0 0"/>
            <geometry>
                <box size="0.5772687024499288 0.8447693069846848 0.7951935655656966" />
            </geometry>
        </collision>
    </link>
    <joint name="Link0_Link1" type="revolute">
       <parent link="Link0"/>
       <child  link="Link1"/>
       <origin rpy="0 0 0" xyz="0 -0.4223846534923424 0" />
     <axis xyz="0.5370990482928342 1.5370990482928342 2.537099048292834"/>
       <limit effort="0.0" lower="-3.14159" upper="3.14159" velocity="0.0"/>
    </joint>
    <link name="Link1">
        <inertial>
            <origin xyz="0 -0.23281132718905267 0" rpy="0 0 0"/>
            <mass value="1" />
            <inertia ixx="100" ixy="0" ixz="0" iyy="100" iyz="0" izz="100" />
        </inertial>
        <visual>
            <origin xyz="0 -0.23281132718905267 0" rpy="0 0 0"/>
            <geometry>
                <box size="0.8104875222865257 0.46562265437810535 0.9441184636990848" />
            </geometry>
            <material name="Blue">
                <color rgba="0 0 1.0 1.0"/>
            </material>
        </visual>
        <collision>
            <origin xyz="0 -0.23281132718905267 0" rpy="0 0 0"/>
            <geometry>
                <box size="0.8104875222865257 0.46562265437810535 0.9441184636990848" />
            </geometry>
        </collision>
    </link>
    <joint name="Link0_Link2" type="revolute">
       <parent link="Link0"/>
       <child  link="Link2"/>
       <origin rpy="0 0 0" xyz="0 0 0" />
     <axis xyz="0.025599389709617504 1.0255993897096176 2.0255993897096176"/>
       <limit effort="0.0" lower="-3.14159" upper="3.14159" velocity="0.0"/>
    </joint>
    <link name="Link2">
        <inertial>
            <origin xyz="0 0.12328641630991516 0" rpy="0 0 0"/>
            <mass value="1" />
            <inertia ixx="100" ixy="0" ixz="0" iyy="100" iyz="0" izz="100" />
        </inertial>
        <visual>
            <origin xyz="0 0.12328641630991516 0" rpy="0 0 0"/>
            <geometry>
                <box size="0.0714076997134121 0.24657283261983032 0.04330759476607582" />
            </geometry>
            <material name="Blue">
                <color rgba="0 0 1.0 1.0"/>
            </material>
        </visual>
        <collision>
            <origin xyz="0 0.12328641630991516 0" rpy="0 0 0"/>
            <geometry>
                <box size="0.0714076997134121 0.24657283261983032 0.04330759476607582" />
            </geometry>
        </collision>
    </link>
    <joint name="Link0_Link3" type="revolute">
       <parent link="Link0"/>
       <child  link="Link3"/>
       <origin rpy="0 0 0" xyz="0 0.4223846534923424 0.3975967827828483" />
     <axis xyz="0.28358506593703914 1.2835850659370391 2.2835850659370394"/>
       <limit effort="0.0" lower="-3.14159" upper="3.14159" velocity="0.0"/>
    </joint>
    <link name="Link3">
        <inertial>
            <origin xyz="0 0 0.185582942920255" rpy="0 0 0"/>
            <mass value="1" />
            <inertia ixx="100" ixy="0" ixz="0" iyy="100" iyz="0" izz="100" />
        </inertial>
        <visual>
            <origin xyz="0 0 0.185582942920255" rpy="0 0 0"/>
            <geometry>
                <box size="0.05994552377252438 0.09776889662911281 0.37116588584051" />
            </geometry>
            <material name="Blue">
                <color rgba="0 0 1.0 1.0"/>
            </material>
        </visual>
        <collision>
            <origin xyz="0 0 0.185582942920255" rpy="0 0 0"/>
            <geometry>
                <box size="0.05994552377252438 0.09776889662911281 0.37116588584051" />
            </geometry>
        </collision>
    </link>
</robot>