<robot name = "robot">
    <link name="Link0">
        <inertial>
            <origin xyz="0 0 0" rpy="0 0 0"/>
            <mass value="1" />
            <inertia ixx="100" ixy="0" ixz="0" iyy="100" iyz="0" izz="100" />
        </inertial>
        <visual>
            <origin xyz="0 0 0" rpy="0 0 0"/>
            <geometry>
                <box size="0.7934475894017761 0.8095176747178948 0.7975469418093027" />
            </geometry>
            <material name="Blue">
                <color rgba="0 0 1.0 1.0"/>
            </material>
        </visual>
        <collision>
            <origin xyz="0 0 0" rpy="0 0 0"/>
            <geometry>
                <box size="0.7934475894017761 0.8095176747178948 0.7975469418093027" />
            </geometry>
        </collision>
    </link>
    <joint name="Link0_Link1" type="revolute">
       <parent link="Link0"/>
       <child  link="Link1"/>
       <origin rpy="0 0 0" xyz="-0.39672379470088803 0 0" />
     <axis xyz="0.03981546366889044 0.9837059795859147 0.47853760169069737"/>
       <limit effort="0.0" lower="-3.14159" upper="3.14159" velocity="0.0"/>
    </joint>
    <link name="Link1">
        <inertial>
            <origin xyz="-0.09271353572833996 0 0" rpy="0 0 0"/>
            <mass value="1" />
            <inertia ixx="100" ixy="0" ixz="0" iyy="100" iyz="0" izz="100" />
        </inertial>
        <visual>
            <origin xyz="-0.09271353572833996 0 0" rpy="0 0 0"/>
            <geometry>
                <box size="0.18542707145667991 0.749936684461131 0.5003290211387642" />
            </geometry>
            <material name="Green">
                <color rgba="0 1.0 0 1.0"/>
            </material>
        </visual>
        <collision>
            <origin xyz="-0.09271353572833996 0 0" rpy="0 0 0"/>
            <geometry>
                <box size="0.18542707145667991 0.749936684461131 0.5003290211387642" />
            </geometry>
        </collision>
    </link>
    <joint name="Link1_Link2" type="revolute">
       <parent link="Link1"/>
       <child  link="Link2"/>
       <origin rpy="0 0 0" xyz="-0.09271353572833996 0.3749683422305655 0" />
     <axis xyz="0.5864853968680906 0.12737873564010183 0.723060586569856"/>
       <limit effort="0.0" lower="-3.14159" upper="3.14159" velocity="0.0"/>
    </joint>
    <link name="Link2">
        <inertial>
            <origin xyz="0 0.035212561152591526 0" rpy="0 0 0"/>
            <mass value="1" />
            <inertia ixx="100" ixy="0" ixz="0" iyy="100" iyz="0" izz="100" />
        </inertial>
        <visual>
            <origin xyz="0 0.035212561152591526 0" rpy="0 0 0"/>
            <geometry>
                <box size="0.08805621961752175 0.07042512230518305 0.2705482273812503" />
            </geometry>
            <material name="Green">
                <color rgba="0 1.0 0 1.0"/>
            </material>
        </visual>
        <collision>
            <origin xyz="0 0.035212561152591526 0" rpy="0 0 0"/>
            <geometry>
                <box size="0.08805621961752175 0.07042512230518305 0.2705482273812503" />
            </geometry>
        </collision>
    </link>
    <joint name="Link2_Link3" type="revolute">
       <parent link="Link2"/>
       <child  link="Link3"/>
       <origin rpy="0 0 0" xyz="0 0.07042512230518305 0" />
     <axis xyz="0.5069417605709553 0.44497441220297074 0.9072537616989708"/>
       <limit effort="0.0" lower="-3.14159" upper="3.14159" velocity="0.0"/>
    </joint>
    <link name="Link3">
        <inertial>
            <origin xyz="0 0.08620269905418837 0" rpy="0 0 0"/>
            <mass value="1" />
            <inertia ixx="100" ixy="0" ixz="0" iyy="100" iyz="0" izz="100" />
        </inertial>
        <visual>
            <origin xyz="0 0.08620269905418837 0" rpy="0 0 0"/>
            <geometry>
                <box size="0.1976532396971713 0.17240539810837674 0.86434497572423" />
            </geometry>
            <material name="Green">
                <color rgba="0 1.0 0 1.0"/>
            </material>
        </visual>
        <collision>
            <origin xyz="0 0.08620269905418837 0" rpy="0 0 0"/>
            <geometry>
                <box size="0.1976532396971713 0.17240539810837674 0.86434497572423" />
            </geometry>
        </collision>
    </link>
</robot>