<robot name = "robot">
    <link name="Link0">
        <inertial>
            <origin xyz="0 0 0" rpy="0 0 0"/>
            <mass value="1" />
            <inertia ixx="100" ixy="0" ixz="0" iyy="100" iyz="0" izz="100" />
        </inertial>
        <visual>
            <origin xyz="0 0 0" rpy="0 0 0"/>
            <geometry>
                <box size="0.6494663578358874 0.7417869892607294 0.7951935655656966" />
            </geometry>
            <material name="Blue">
                <color rgba="0 0 1.0 1.0"/>
            </material>
        </visual>
        <collision>
            <origin xyz="0 0 0" rpy="0 0 0"/>
            <geometry>
                <box size="0.6494663578358874 0.7417869892607294 0.7951935655656966" />
            </geometry>
        </collision>
    </link>
    <joint name="Link0_Link1" type="revolute">
       <parent link="Link0"/>
       <child  link="Link1"/>
       <origin rpy="0 0 0" xyz="0 -0.3708934946303647 0" />
     <axis xyz="0.821461226302127 1.821461226302127 2.821461226302127"/>
       <limit effort="0.0" lower="-3.14159" upper="3.14159" velocity="0.0"/>
    </joint>
    <link name="Link1">
        <inertial>
            <origin xyz="0 -0.23049856199408641 0" rpy="0 0 0"/>
            <mass value="1" />
            <inertia ixx="100" ixy="0" ixz="0" iyy="100" iyz="0" izz="100" />
        </inertial>
        <visual>
            <origin xyz="0 -0.23049856199408641 0" rpy="0 0 0"/>
            <geometry>
                <box size="0.029005228283614737 0.46099712398817283 0.9433567169983137" />
            </geometry>
            <material name="Blue">
                <color rgba="0 0 1.0 1.0"/>
            </material>
        </visual>
        <collision>
            <origin xyz="0 -0.23049856199408641 0" rpy="0 0 0"/>
            <geometry>
                <box size="0.029005228283614737 0.46099712398817283 0.9433567169983137" />
            </geometry>
        </collision>
    </link>
    <joint name="Link1_Link2" type="revolute">
       <parent link="Link1"/>
       <child  link="Link2"/>
       <origin rpy="0 0 0" xyz="0 -0.46099712398817283 0" />
     <axis xyz="0.6489745531369242 1.6489745531369242 2.648974553136924"/>
       <limit effort="0.0" lower="-3.14159" upper="3.14159" velocity="0.0"/>
    </joint>
    <link name="Link2">
        <inertial>
            <origin xyz="0 -0.01832339715656267 0" rpy="0 0 0"/>
            <mass value="1" />
            <inertia ixx="100" ixy="0" ixz="0" iyy="100" iyz="0" izz="100" />
        </inertial>
        <visual>
            <origin xyz="0 -0.01832339715656267 0" rpy="0 0 0"/>
            <geometry>
                <box size="0.6893157595374508 0.03664679431312534 0.08116875580842231" />
            </geometry>
            <material name="Blue">
                <color rgba="0 0 1.0 1.0"/>
            </material>
        </visual>
        <collision>
            <origin xyz="0 -0.01832339715656267 0" rpy="0 0 0"/>
            <geometry>
                <box size="0.6893157595374508 0.03664679431312534 0.08116875580842231" />
            </geometry>
        </collision>
    </link>
    <joint name="Link1_Link3" type="revolute">
       <parent link="Link1"/>
       <child  link="Link3"/>
       <origin rpy="0 0 0" xyz="0 -0.23049856199408641 0.47167835849915685" />
     <axis xyz="0.18323454340276812 1.1832345434027682 2.1832345434027682"/>
       <limit effort="0.0" lower="-3.14159" upper="3.14159" velocity="0.0"/>
    </joint>
    <link name="Link3">
        <inertial>
            <origin xyz="0 0 0.38286272581457087" rpy="0 0 0"/>
            <mass value="1" />
            <inertia ixx="100" ixy="0" ixz="0" iyy="100" iyz="0" izz="100" />
        </inertial>
        <visual>
            <origin xyz="0 0 0.38286272581457087" rpy="0 0 0"/>
            <geometry>
                <box size="0.17420062794249325 0.762572364876913 0.7657254516291417" />
            </geometry>
            <material name="Blue">
                <color rgba="0 0 1.0 1.0"/>
            </material>
        </visual>
        <collision>
            <origin xyz="0 0 0.38286272581457087" rpy="0 0 0"/>
            <geometry>
                <box size="0.17420062794249325 0.762572364876913 0.7657254516291417" />
            </geometry>
        </collision>
    </link>
</robot>